Workbook

Sheet Rawdata_Index 
B1: Індекс споживчих цін загальний | C1: Продукти харчування | D1: Одяг і взуття | E1: Комунальні платежі | F1: Предмети домашнього вжитку | G1: Охорона здоров’я | H1: Транспорт | I1: Зв’язок | J1: Відпочинок і культура | K1: Освіта | L1: Ресторани та готел | M1: Усього Будівлі | N1: Житлові будинки | O1: Нежитлові будівлі | P1: Індекс цін на житло Первинний ринок | Q1: Індекс цін на житло Вторинний ринок
A2: 2018 | B2: 110.9 | C2: 111.1 | D2: 101.8 | E2: 106.8 | F2: 106.1 | G2: 108.8 | H2: 115.7 | I2: 111 | J2: 104.4 | K2: 114.6 | L2: 115.3 | M2: 122.6 | N2: 122.6 | O2: 122.6 | P2: 105.4 | Q2: 105
A3: 2019 | B3: 107.9 | C3: 108 | D3: 100.2 | E3: 108 | F3: 102.9 | G3: 106.7 | H3: 104.1 | I3: 115.5 | J3: 102.4 | K3: 113.4 | L3: 111.1 | M3: 106.5 | N3: 108.4 | O3: 104.7 | P3: 106.6 | Q3: 111.1
A4: 2020 | B4: 102.7 | C4: 102.7 | D4: 95.4 | E4: 97 | F4: 99.3 | G4: 105.3 | H4: 98.1 | I4: 106.5 | J4: 98.2 | K4: 113.6 | L4: 105.9 | M4: 103 | N4: 104.8 | O4: 101.3 | P4: 106.9 | Q4: 109.8
A5: 2021 | B5: 109.4 | C5: 110.8 | D5: 95.5 | E5: 123.2 | F5: 102.9 | G5: 106.6 | H5: 110 | I5: 105.2 | J5: 103.3 | K5: 115.3 | L5: 106.1 | M5: 114.4 | N5: 112.4 | O5: 115.9 | P5: 113.5 | Q5: 115.7
A6: 2022 | B6: 120.2 | C6: 126.6 | D6: 97.3 | E6: 105.1 | F6: 116.1 | G6: 114.5 | H6: 131.8 | I6: 110.9 | J6: 110.9 | K6: 114.1 | L6: 116.1 | M6: 128.3 | N6: 127.8 | O6: 128.3 | P6: 114.6 | Q6: 112.1
A7: 2023 | B7: 112.9 | C7: 114.7 | D7: 99.5 | E7: 110 | F7: 112.7 | G7: 112.8 | H7: 112.1 | I7: 107.8 | J7: 107.3 | K7: 110.7 | L7: 118.5 | M7: 115.7 | N7: 116.3 | O7: 115.5 | P7: 112.8 | Q7: 115.6
A8: 2024 | B8: 106.5 | C8: 104.9 | D8: 94.5 | E8: 116.4 | F8: 100 | G8: 110.7 | H8: 107.2 | I8: 102.5 | J8: 98.7 | K8: 111.9 | L8: 111.6 | M8: 108.2 | N8: 108.6 | O8: 107.9 | P8: 115 | Q8: 111.6
A9: 2025 | B9: 112.7 | C9: 117.4 | D9: 95 | E9: 108.9 | F9: 102 | G9: 111.7 | H9: 107.2 | I9: 117.1 | J9: 100.6 | K9: 113 | L9: 114.5 | M9: 106.1 | N9: 106.3 | O9: 106 | P9: 114.3 | Q9: 112
B11: Індекс споживчих цін загальний | C11: Продукти харчування | D11: Одяг і взуття | E11: Комунальні платежі | F11: Предмети домашнього вжитку | G11: Охорона здоров’я | H11: Транспорт | I11: Зв’язок | J11: Відпочинок і культура | K11: Освіта | L11: Ресторани та готел | M11: Усього Будівлі | N11: Житлові будинки | O11: Нежитлові будівлі | P11: Індекс цін на житло Первинний ринок | Q11: Індекс цін на житло Вторинний ринок
A12: 2018 | B12: =B2/100 -> 1.109 | C12: =C2/100 -> 1.111 | D12: =D2/100 -> 1.018 | E12: =E2/100 -> 1.068 | F12: =F2/100 -> 1.061 | G12: =G2/100 -> 1.088 | H12: =H2/100 -> 1.157 | I12: =I2/100 -> 1.11 | ... Q12: =Q2/100 -> 1.05
A13: 2019 | B13: =B3/100 -> 1.079 | C13: =C3/100 -> 1.08 | D13: =D3/100 -> 1.002 | E13: =E3/100 -> 1.08 | F13: =F3/100 -> 1.029 | G13: =G3/100 -> 1.067 | H13: =H3/100 -> 1.041 | I13: =I3/100 -> 1.155 | ... Q13: =Q3/100 -> 1.111
A14: 2020 | B14: =B4/100 -> 1.027 | C14: =C4/100 -> 1.027 | D14: =D4/100 -> 0.954 | E14: =E4/100 -> 0.97 | F14: =F4/100 -> 0.993 | G14: =G4/100 -> 1.053 | H14: =H4/100 -> 0.981 | I14: =I4/100 -> 1.065 | ... Q14: =Q4/100 -> 1.098
A15: 2021 | B15: =B5/100 -> 1.094 | C15: =C5/100 -> 1.108 | D15: =D5/100 -> 0.955 | E15: =E5/100 -> 1.232 | F15: =F5/100 -> 1.029 | G15: =G5/100 -> 1.066 | H15: =H5/100 -> 1.1 | I15: =I5/100 -> 1.052 | ... Q15: =Q5/100 -> 1.157
A16: 2022 | B16: =B6/100 -> 1.202 | C16: =C6/100 -> 1.266 | D16: =D6/100 -> 0.973 | E16: =E6/100 -> 1.051 | F16: =F6/100 -> 1.161 | G16: =G6/100 -> 1.145 | H16: =H6/100 -> 1.318 | I16: =I6/100 -> 1.109 | ... Q16: =Q6/100 -> 1.121
A17: 2023 | B17: =B7/100 -> 1.129 | C17: =C7/100 -> 1.147 | D17: =D7/100 -> 0.995 | E17: =E7/100 -> 1.1 | F17: =F7/100 -> 1.127 | G17: =G7/100 -> 1.128 | H17: =H7/100 -> 1.121 | I17: =I7/100 -> 1.078 | ... Q17: =Q7/100 -> 1.156
A18: 2024 | B18: =B8/100 -> 1.065 | C18: =C8/100 -> 1.049 | D18: =D8/100 -> 0.945 | E18: =E8/100 -> 1.164 | F18: =F8/100 -> 1 | G18: =G8/100 -> 1.107 | H18: =H8/100 -> 1.072 | I18: =I8/100 -> 1.025 | ... Q18: =Q8/100 -> 1.116
A19: 2025 | B19: =B9/100 -> 1.127 | C19: =C9/100 -> 1.174 | D19: =D9/100 -> 0.95 | E19: =E9/100 -> 1.089 | F19: =F9/100 -> 1.02 | G19: =G9/100 -> 1.117 | H19: =H9/100 -> 1.072 | I19: =I9/100 -> 1.171 | ... Q19: =Q9/100 -> 1.12

Sheet Rawdata m2
B1: Загальна площа житлових будинків на початок будівництва2, тис. м2 | C1: Загальна площа нежитлових будівель на початок будівництва,тис. м2 | D1: Загальна площа житлових будинків, прийнятих в експлуатацію, тис. м2 | E1: Загальна площа нежитлових будівель, прийнятих в експлуатацію, тис. м2
A2: 2018 | B2: =12873616 -> 12873616 | C2: 3832437 | D2: 8689356 | E2: 2908378
A3: 2019 | B3: 14700707 | C3: 5307329 | D3: 11029327 | E3: 3962270
A4: 2020 | B4: 7514310 | C4: 3791885 | D4: 8451221 | E4: 3444193
A5: 2021 | B5: 12714908 | C5: 6241656 | D5: 11433790 | E5: 4948874
A6: 2022 | B6: 6668984 | C6: 2538074 | D6: 7110224 | E6: 2493070
A7: 2023 | B7: 4205318 | C7: 2866693 | D7: 7380752 | E7: 2340350
A8: 2024 | B8: 3903400 | C8: 4414153 | D8: 9758881 | E8: 2690954
A9: 2025 | B9: 5829884 | C9: 4140865 | D9: 9552933 | E9: 3268408

Sheet Index_analisys
B1: Індекс споживчих цін загальний | C1: Продукти харчування | D1: Одяг і взуття | E1: Комунальні платежі | F1: Предмети домашнього вжитку | G1: Охорона здоров’я | H1: Транспорт | I1: Зв’язок | J1: Відпочинок і культура | K1: Освіта | L1: Ресторани та готел | M1: Будівлі | N1: Житлові будинки | O1: Нежитлові будівлі | P1: Індекс цін на житло Первинний ринок | Q1: Індекс цін на житло Вторинний ринок
A2: 2018-2025 | B2: ='Rawdata_Index '!B12*'Rawdata_Index '!B13*'Rawdata_Index '!B14*'Rawdata_Index '!B15*'Rawdata_Index '!B16*'Rawdata_Index '!B17*'Rawdata_Index '!B18*'Rawdata_Index '!B19 -> 2.1898415 | C2: ='Rawdata_Index '!C12*'Rawdata_Index '!C13*'Rawdata_Index '!C14*'Rawdata_Index '!C15*'Rawdata_Index '!C16*'Rawdata_Index '!C17*'Rawdata_Index '!C18*'Rawdata_Index '!C19 -> 2.4416799 | D2: ='Rawdata_Index '!D12*'Rawdata_Index '!D13*'Rawdata_Index '!D14*'Rawdata_Index '!D15*'Rawdata_Index '!D16*'Rawdata_Index '!D17*'Rawdata_Index '!D18*'Rawdata_Index '!D19 -> 0.8077158 | E2: ='Rawdata_Index '!E12*'Rawdata_Index '!E13*'Rawdata_Index '!E14*'Rawdata_Index '!E15*'Rawdata_Index '!E16*'Rawdata_Index '!E17*'Rawdata_Index '!E18*'Rawdata_Index '!E19 -> 2.0200109 | F2: ='Rawdata_Index '!F12*'Rawdata_Index '!F13*'Rawdata_Index '!F14*'Rawdata_Index '!F15*'Rawdata_Index '!F16*'Rawdata_Index '!F17*'Rawdata_Index '!F18*'Rawdata_Index '!F19 -> 1.4888526 | G2: ='Rawdata_Index '!G12*'Rawdata_Index '!G13*'Rawdata_Index '!G14*'Rawdata_Index '!G15*'Rawdata_Index '!G16*'Rawdata_Index '!G17*'Rawdata_Index '!G18*'Rawdata_Index '!G19 -> 2.0811063 | H2: ='Rawdata_Index '!H12*'Rawdata_Index '!H13*'Rawdata_Index '!H14*'Rawdata_Index '!H15*'Rawdata_Index '!H16*'Rawdata_Index '!H17*'Rawdata_Index '!H18*'Rawdata_Index '!H19 -> 2.2067665 | I2: ='Rawdata_Index '!I12*'Rawdata_Index '!I13*'Rawdata_Index '!I14*'Rawdata_Index '!I15*'Rawdata_Index '!I16*'Rawdata_Index '!I17*'Rawdata_Index '!I18*'Rawdata_Index '!I19 -> 2.061111 | ... Q2: ='Rawdata_Index '!Q12*'Rawdata_Index '!Q13*'Rawdata_Index '!Q14*'Rawdata_Index '!Q15*'Rawdata_Index '!Q16*'Rawdata_Index '!Q17*'Rawdata_Index '!Q18*'Rawdata_Index '!Q19 -> 2.4004061
B28: Будівлі | C28: Житлові будинки | D28: Нежитлові будівлі | E28: Первинний ринок квартир | F28: Вторинний ринок квартир
A29: 2017-2025 | B29: =M2 -> 2.6218388 | C29: =N2 -> 2.6860927 | D29: =O2 -> 2.5542652 | E29: =P2 -> 2.3163766 | F29: =Q2 -> 2.4004061

Sheet m_2analisys
B1: Загальна площа житлових будинків на початок будівництва2, тис. м2 | C1: Загальна площа нежитлових будівель на початок будівництва,тис. м2 | I1: Загальна площа житлових будинків, прийнятих в експлуатацію, тис. м2 | J1: Загальна площа нежитлових будівель, прийнятих в експлуатацію, тис. м2
A2: 2018 | B2: ='Rawdata m2'!B2/1000 -> 12873.616 | C2: ='Rawdata m2'!C2/1000 -> 3832.437 | H2: 2018 | I2: ='Rawdata m2'!D2/1000 -> 8689.356 | J2: ='Rawdata m2'!E2/1000 -> 2908.378
A3: 2019 | B3: ='Rawdata m2'!B3/1000 -> 14700.707 | C3: ='Rawdata m2'!C3/1000 -> 5307.329 | H3: 2019 | I3: ='Rawdata m2'!D3/1000 -> 11029.327 | J3: ='Rawdata m2'!E3/1000 -> 3962.27
A4: 2020 | B4: ='Rawdata m2'!B4/1000 -> 7514.31 | C4: ='Rawdata m2'!C4/1000 -> 3791.885 | H4: 2020 | I4: ='Rawdata m2'!D4/1000 -> 8451.221 | J4: ='Rawdata m2'!E4/1000 -> 3444.193
A5: 2021 | B5: ='Rawdata m2'!B5/1000 -> 12714.908 | C5: ='Rawdata m2'!C5/1000 -> 6241.656 | H5: 2021 | I5: ='Rawdata m2'!D5/1000 -> 11433.79 | J5: ='Rawdata m2'!E5/1000 -> 4948.874
A6: 2022 | B6: ='Rawdata m2'!B6/1000 -> 6668.984 | C6: ='Rawdata m2'!C6/1000 -> 2538.074 | H6: 2022 | I6: ='Rawdata m2'!D6/1000 -> 7110.224 | J6: ='Rawdata m2'!E6/1000 -> 2493.07
A7: 2023 | B7: ='Rawdata m2'!B7/1000 -> 4205.318 | C7: ='Rawdata m2'!C7/1000 -> 2866.693 | H7: 2023 | I7: ='Rawdata m2'!D7/1000 -> 7380.752 | J7: ='Rawdata m2'!E7/1000 -> 2340.35
A8: 2024 | B8: ='Rawdata m2'!B8/1000 -> 3903.4 | C8: ='Rawdata m2'!C8/1000 -> 4414.153 | H8: 2024 | I8: ='Rawdata m2'!D8/1000 -> 9758.881 | J8: ='Rawdata m2'!E8/1000 -> 2690.954
A9: 2025 | B9: ='Rawdata m2'!B9/1000 -> 5829.884 | C9: ='Rawdata m2'!C9/1000 -> 4140.865 | H9: 2025 | I9: 9553 | J9: 3268

Sheet Лист2
B2: https://public.tableau.com/app/profile/valentyna.mamenko/viz/_17770600434550/Dashboard3?publish=yes

Sheet Rawdata_flat
B1: Кількість квартир у житлових будинках на початок будівництва, одиниць | C1: Кількість квартир у житлових будинках, прийнятих в експлуатацію, одиниць
A3: 2018 | B3: 166991 | C3: 103141
A4: 2019 | B4: 188964 | C4: 125986
A5: 2020 | B5: 112109 | C5: 96504
A6: 2021 | B6: 170754 | C6: 151720
A7: 2022 | B7: 98386 | C7: 92593
A8: 2023 | B8: 66831 | C8: 89255
A9: 2024 | B9: 69294 | C9: 118452
A10: 2025 | B10: 97078 | C10: 117578

Sheet Contracts analisys
A1: КІЛЬКІСТЬ УГОД НЕРУХОМОСТІ (2010–2025) по різним оцінкам та відомостям
A3: Рік | B3: Угоди (тис.) | C3: Коментар | G3: https://minfin.com.ua/ua/2026/04/18/172186266/
A4: 2010 | B4: ~350–400 | G4: https://minfin.com.ua/ua/2026/04/21/172369878/
A5: 2011 | B5: ~360–410
A6: 2012 | B6: ~370–420 | G6: https://epravda.com.ua/biznes/rinok-neruhomosti-ukrajini-2025-trendi-cini-ipoteka-ta-prognoz-na-2026-815522/
A7: 2013 | B7: ~360–400
A8: 2014 | B8: ~250–300 | C8: війна, девальвація гривні | G8: https://oksagen.ua/uk/novosti/dynamika-rynku-neruhomosti-ukrayiny-na-pochatku-2025-roku/
A9: 2015 | B9: ~220–270
A10: 2016 | B10: ~250–300 | G10: https://www.rbc.ua/rus/news/rinok-vtorinki-pidskochiv-15-rik-de-ukrayini-1772450631.html
A11: 2017 | B11: ~280–330
A12: 2018 | B12: ~320–370 | G12: https://retailers.ua/news/menedjment/yak-pratsyuvav-rinok-neruhomosti-u-2025-rotsi-chi-zbilshilas-kilkist-ugod/
A13: 2019 | B13: ~350–400 | C13: пік перед COVID
A14: 2020 | B14: ~300–340 | C14: COVID | G14: https://lun.ua/stat/sale/ukraine?srsltid=AfmBOoq3-JdSFvH56Z9quLG2HmLOpFAzwxr62S0y1BR2CrU_3vmcMCAW
A15: 2021 | B15: ~450–500 | C15: пік ринку
A16: 2022 | B16: ~150–180 | C16: повномасштабна війна | G16: https://lun.ua/stat/sale/ukraine?srsltid=AfmBOoq3-JdSFvH56Z9quLG2HmLOpFAzwxr62S0y1BR2CrU_3vmcMCAW
A17: 2023 | B17: ~170–230 | G17: https://centraljust.gov.ua/news/info/notariat-u-tsifrah-pidsumki-2024-roku
A18: 2024 | B18: ~452 | C18: офіційно Мін’юст пік ринку | G18: https://budport.com.ua/buildnews/28186-minyust-vidzvituvav-pro-kilkist-kvartir-i-budinkiv-prodanih-u-2023-roci
A19: 2025 | B19: ~366.7 | C19: падіння -9.8% | G19: https://retailers.ua/news/menedjment/yak-pratsyuvav-rinok-neruhomosti-u-2025-rotsi-chi-zbilshilas-kilkist-ugod/
G21: https://fiu.gov.ua/assets/userfiles/books/6_sektor_ozinka_zvit.pdf

Sheet Lun_price
B1: Ціни на первинному ринку по містах (Україна) | D1: Ціни на вторинному ринку по містах (Україна)
A3: Регіон / місто | B3: Орієнтовна ціна медіанна ціна найдешевшої квартири (млн. грн) | C3: Орієнтовна ціна медіанна ціна найдешевшої квартири (млн. грн) | D3: Орієнтовна ціна медіанна найдешевшої квартири ($) | E3: Орієнтовна ціна будинку ($) | F3: Орієнтовна ціна будинку ($) | G3: Ціна будинку за м 2 ($) | H3: Ціна будинку за м 2 ($)
B4: Місто | C4: Область | E4: Місто | F4: Область | G4: Місто | H4: Область
A5: Київ | B5: 2.6 | C5: 1.6 | D5: 70 | E5: 220 | F5: 119 | G5: 1250 | H5: 936
A6: Одеса | B6: 2 | C6: 1.3 | D6: 49.5 | E6: 160 | F6: 62 | G6: 1050 | H6: 545
A7: Львів | B7: 2.2 | C7: 2.1 | D7: 71.9 | E7: 216 | F7: 85 | G7: 1410 | H7: 672
A8: Дніпро | B8: 1.1 | C8: 1.5 | D8: 34.2 | E8: 55 | F8: 25 | G8: 588 | H8: 344
A9: Івано-Франківськ | B9: 1.7 | C9: 2.1 | D9: 41.3 | E9: 145 | F9: 86.5 | G9: 962 | H9: 658
A10: Чернівці | B10: 2 | C10: 1.9 | D10: 58 | E10: 27.5 | F10: 41.2 | G10: 914 | H10: 394
A11: Полтава | B11: 1.7 | C11: 1.5 | D11: 39.3 | E11: 53 | F11: 18 | G11: 622 | H11: 286
A12: Хмельницький | B12: 1.5 | C12: 1.5 | D12: 40.5 | E12: 85 | F12: 27 | G12: 703 | H12: 311
A13: Черкаси | B13: 1.5 | C13: 1.9 | D13: 45 | E13: 78 | F13: 20 | G13: 923 | H13: 272
A14: Харків | B14: 1.4 | C14: 1 | D14: 23 | E14: 88.5 | F14: 24 | G14: 667 | H14: 313
A15: Суми | B15: 1 | C15: 1.3 | D15: 26 | E15: 55 | F15: 13 | G15: 534 | H15: 191
A16: Миколаїв | B16: 1.1 | C16: 2 | D16: 20 | E16: 35 | F16: 13.5 | G16: 430 | H16: 187
... A25: Ужгород | B25: 2.2 | C25: 1.8 | D25: 70 | E25: 173 | F25: 70 | G25: 1180 | H25: 564

Sheet Raw data _m2region begin
A1: Показник | B1: Територіальний розріз | C1: Тип будівлі | D1: Одиниця виміру | E1: Примітки набору даних | F1: Примітки часового ряду | G1: Примітки спостереження | H1: 2018 | I1: 2019 | J1: 2020 | K1: 2021 | L1: 2022 | M1: 2023 | N1: 2024 | O1: 2025
A2: Загальна площа житлових будинків і нежитлових будівель на початок будівництва | B2: Волинська | C2: Житлові будинки | D2: Квадратний метр | E2: З 01.01.2024 року назви щодо типів будівель наведено відповідно до Національного класифікатора будівель і споруд (наказ Мінекономіки України від 16.05.2023 № 3573), до 01.01.2024 року - Номенклатури продукції будівництва (наказ Держстату України від 29.12.2017 № 356 (із змінами)). З 2025 року дані за показниками у розрізі типів місцевості (сільська, міська) та щодо загальної площі житлових будинків, прийнятих в експлуатацію, у розрахунку на 1 тис. осіб населення не формуються. З 2026 року за показниками змінено розріз за видами будівель. | F2: 1. Без урахування даних щодо житлових будинків та нежитлових будівель, показники за якими відсутні у Повідомленні про початок виконання будівельних робіт (Постанова КМУ від 13.04.2011 №466 (із змінами)); з 01.01.2024 року з урахуванням дач та садових будинків у житлових будинках. 2. Показники наведено наростаючим підсумком. | H2: 171404 | I2: 206927 | J2: 90025 | K2: 179401 | L2: 425185 | M2: 103321 | N2: 164273 | O2: 195880
A3: Загальна площа житлових будинків і нежитлових будівель на початок будівництва | B3: Дніпропетровська | C3: Житлові будинки | D3: Квадратний метр | E3: З 01.01.2024 року назви щодо типів будівель наведено відповідно до Національного класифікатора будівель і споруд (наказ Мінекономіки України від 16.05.2023 № 3573), до 01.01.2024 року - Номенклатури продукції будівництва (наказ Держстату України від 29.12.2017 № 356 (із змінами)). З 2025 року дані за показниками у розрізі типів місцевості (сільська, міська) та щодо загальної площі житлових будинків, прийнятих в експлуатацію, у розрахунку на 1 тис. осіб населення не формуються. З 2026 року за показниками змінено розріз за видами будівель. | F3: 1. Без урахування даних щодо житлових будинків та нежитлових будівель, показники за якими відсутні у Повідомленні про початок виконання будівельних робіт (Постанова КМУ від 13.04.2011 №466 (із змінами)); з 01.01.2024 року з урахуванням дач та садових будинків у житлових будинках. 2. Показники наведено наростаючим підсумком. | G3: Відомості відсутні. | H3: 241486 | I3: 334018 | J3: 290413 | K3: 682186 | L3: 155722 | M3: 116080 | N3: 75795 | O3: 23867
A4: Загальна площа житлових будинків і нежитлових будівель на початок будівництва | B4: Вінницька | C4: Житлові будинки | D4: Квадратний метр | E4: З 01.01.2024 року назви щодо типів будівель наведено відповідно до Національного класифікатора будівель і споруд (наказ Мінекономіки України від 16.05.2023 № 3573), до 01.01.2024 року - Номенклатури продукції будівництва (наказ Держстату України від 29.12.2017 № 356 (із змінами)). З 2025 року дані за показниками у розрізі типів місцевості (сільська, міська) та щодо загальної площі житлових будинків, прийнятих в експлуатацію, у розрахунку на 1 тис. осіб населення не формуються. З 2026 року за показниками змінено розріз за видами будівель. | F4: 1. Без урахування даних щодо житлових будинків та нежитлових будівель, показники за якими відсутні у Повідомленні про початок виконання будівельних робіт (Постанова КМУ від 13.04.2011 №466 (із змінами)); з 01.01.2024 року з урахуванням дач та садових будинків у житлових будинках. 2. Показники наведено наростаючим підсумком. | H4: 332720 | I4: 156010 | J4: 120348 | K4: 214744 | L4: 129969 | M4: 230614 | N4: 315159 | O4: 179491
A5: Загальна площа житлових будинків і нежитлових будівель на початок будівництва | B5: Донецька | C5: Житлові будинки | D5: Квадратний метр | E5: З 01.01.2024 року назви щодо типів будівель наведено відповідно до Національного класифікатора будівель і споруд (наказ Мінекономіки України від 16.05.2023 № 3573), до 01.01.2024 року - Номенклатури продукції будівництва (наказ Держстату України від 29.12.2017 № 356 (із змінами)). З 2025 року дані за показниками у розрізі типів місцевості (сільська, міська) та щодо загальної площі житлових будинків, прийнятих в експлуатацію, у розрахунку на 1 тис. осіб населення не формуються. З 2026 року за показниками змінено розріз за видами будівель. | F5: 1. Дані наведено без урахування тимчасово окупованих російською федерацією територій та частини територій, на яких ведуться (велися) бойові дії. 2. Без урахування даних щодо житлових будинків та нежитлових будівель, показники за якими відсутні у Повідомленні про початок виконання будівельних робіт (Постанова КМУ від 13.04.2011 №466 (із змінами)); з 01.01.2024 року з урахуванням дач та садових будинків у житлових будинках. 3. Показники наведено наростаючим підсумком. | G5: Дані не оприлюднюються з метою виконання вимог Закону України "Про офіційну статистику" щодо забезпечення гарантій органів державної статистики щодо статистичної конфіденційності та/або відповідно до Закону України "Про захист інтересів суб’єктів подання звітності та інших документів у період дії воєнного стану або стану війни. | H5: 4254 | J5: 26297 | K5: 47811 | N5: 794
A6: Загальна площа житлових будинків і нежитлових будівель на початок будівництва | B6: Закарпатська | C6: Житлові будинки | D6: Квадратний метр | E6: З 01.01.2024 року назви щодо типів будівель наведено відповідно до Національного класифікатора будівель і споруд (наказ Мінекономіки України від 16.05.2023 № 3573), до 01.01.2024 року - Номенклатури продукції будівництва (наказ Держстату України від 29.12.2017 № 356 (із змінами)). З 2025 року дані за показниками у розрізі типів місцевості (сільська, міська) та щодо загальної площі житлових будинків, прийнятих в експлуатацію, у розрахунку на 1 тис. осіб населення не формуються. З 2026 року за показниками змінено розріз за видами будівель. | F6: 1. Без урахування даних щодо житлових будинків та нежитлових будівель, показники за якими відсутні у Повідомленні про початок виконання будівельних робіт (Постанова КМУ від 13.04.2011 №466 (із змінами)); з 01.01.2024 року з урахуванням дач та садових будинків у житлових будинках. 2. Показники наведено наростаючим підсумком. | H6: 146891 | I6: 167768 | J6: 146447 | K6: 210655 | L6: 142749 | M6: 256032 | N6: 370187 | O6: 466318
A7: Загальна площа житлових будинків і нежитлових будівель на початок будівництва | B7: Житомирська | C7: Житлові будинки | D7: Квадратний метр | E7: З 01.01.2024 року назви щодо типів будівель наведено відповідно до Національного класифікатора будівель і споруд (наказ Мінекономіки України від 16.05.2023 № 3573), до 01.01.2024 року - Номенклатури продукції будівництва (наказ Держстату України від 29.12.2017 № 356 (із змінами)). З 2025 року дані за показниками у розрізі типів місцевості (сільська, міська) та щодо загальної площі житлових будинків, прийнятих в експлуатацію, у розрахунку на 1 тис. осіб населення не формуються. З 2026 року за показниками змінено розріз за видами будівель. | F7: 1. Без урахування даних щодо житлових будинків та нежитлових будівель, показники за якими відсутні у Повідомленні про початок виконання будівельних робіт (Постанова КМУ від 13.04.2011 №466 (із змінами)); з 01.01.2024 року з урахуванням дач та садових будинків у житлових будинках. 2. Показники наведено наростаючим підсумком. | H7: 84439 | I7: 64476 | J7: 47682 | K7: 113938 | L7: 70020 | M7: 66274 | N7: 139452 | O7: 63081
A8: Загальна площа житлових будинків і нежитлових будівель на початок будівництва | B8: Україна | C8: Житлові будинки | D8: Квадратний метр | E8: З 01.01.2024 року назви щодо типів будівель наведено відповідно до Національного класифікатора будівель і споруд (наказ Мінекономіки України від 16.05.2023 № 3573), до 01.01.2024 року - Номенклатури продукції будівництва (наказ Держстату України від 29.12.2017 № 356 (із змінами)). З 2025 року дані за показниками у розрізі типів місцевості (сільська, міська) та щодо загальної площі житлових будинків, прийнятих в експлуатацію, у розрахунку на 1 тис. осіб населення не формуються. З 2026 року за показниками змінено розріз за видами будівель. | F8: 1. Дані наведено без урахування тимчасово окупованих російською федерацією територій та частини територій, на яких ведуться (велися) бойові дії. 2. Без урахування даних щодо житлових будинків та нежитлових будівель, показники за якими відсутні у Повідомленні про початок виконання будівельних робіт (Постанова КМУ від 13.04.2011 №466 (із змінами)); з 01.01.2024 року з урахуванням дач та садових будинків у житлових будинках. 3. Показники наведено наростаючим підсумком. | H8: 12873616 | I8: 14700707 | J8: 7514310 | K8: 12714908 | L8: 6668984 | M8: 4205318 | N8: 3903400 | O8: 5829884
A9: Загальна площа житлових будинків і нежитлових будівель на початок будівництва | B9: Івано-Франківська | C9: Житлові будинки | D9: Квадратний метр | E9: З 01.01.2024 року назви щодо типів будівель наведено відповідно до Національного класифікатора будівель і споруд (наказ Мінекономіки України від 16.05.2023 № 3573), до 01.01.2024 року - Номенклатури продукції будівництва (наказ Держстату України від 29.12.2017 № 356 (із змінами)). З 2025 року дані за показниками у розрізі типів місцевості (сільська, міська) та щодо загальної площі житлових будинків, прийнятих в експлуатацію, у розрахунку на 1 тис. осіб населення не формуються. З 2026 року за показниками змінено розріз за видами будівель. | F9: 1. Без урахування даних щодо житлових будинків та нежитлових будівель, показники за якими відсутні у Повідомленні про початок виконання будівельних робіт (Постанова КМУ від 13.04.2011 №466 (із змінами)); з 01.01.2024 року з урахуванням дач та садових будинків у житлових будинках. 2. Показники наведено наростаючим підсумком. | H9: 416689 | I9: 748748 | J9: 461123 | K9: 244551 | L9: 204427 | M9: 469035 | N9: 342609 | O9: 523068
A10: Загальна площа житлових будинків і нежитлових будівель на початок будівництва | B10: Одеська | C10: Житлові будинки | D10: Квадратний метр | E10: З 01.01.2024 року назви щодо типів будівель наведено відповідно до Національного класифікатора будівель і споруд (наказ Мінекономіки України від 16.05.2023 № 3573), до 01.01.2024 року - Номенклатури продукції будівництва (наказ Держстату України від 29.12.2017 № 356 (із змінами)). З 2025 року дані за показниками у розрізі типів місцевості (сільська, міська) та щодо загальної площі житлових будинків, прийнятих в експлуатацію, у розрахунку на 1 тис. осіб населення не формуються. З 2026 року за показниками змінено розріз за видами будівель. | F10: 1. Без урахування даних щодо житлових будинків та нежитлових будівель, показники за якими відсутні у Повідомленні про початок виконання будівельних робіт (Постанова КМУ від 13.04.2011 №466 (із змінами)); з 01.01.2024 року з урахуванням дач та садових будинків у житлових будинках. 2. Показники наведено наростаючим підсумком. | H10: 1544541 | I10: 1269707 | J10: 656534 | K10: 1159377 | L10: 265317 | M10: 120436 | N10: 74350 | O10: 24689
A11: Загальна площа житлових будинків і нежитлових будівель на початок будівництва | B11: Кіровоградська | C11: Житлові будинки | D11: Квадратний метр | E11: З 01.01.2024 року назви щодо типів будівель наведено відповідно до Національного класифікатора будівель і споруд (наказ Мінекономіки України від 16.05.2023 № 3573), до 01.01.2024 року - Номенклатури продукції будівництва (наказ Держстату України від 29.12.2017 № 356 (із змінами)). З 2025 року дані за показниками у розрізі типів місцевості (сільська, міська) та щодо загальної площі житлових будинків, прийнятих в експлуатацію, у розрахунку на 1 тис. осіб населення не формуються. З 2026 року за показниками змінено розріз за видами будівель. | F11: 1. Без урахування даних щодо житлових будинків та нежитлових будівель, показники за якими відсутні у Повідомленні про початок виконання будівельних робіт (Постанова КМУ від 13.04.2011 №466 (із змінами)); з 01.01.2024 року з урахуванням дач та садових будинків у житлових будинках. 2. Показники наведено наростаючим підсумком. | G11: Дані не оприлюднюються з метою виконання вимог Закону України "Про офіційну статистику" щодо забезпечення гарантій органів державної статистики щодо статистичної конфіденційності та/або відповідно до Закону України "Про захист інтересів суб’єктів подання звітності та інших документів у період дії воєнного стану або стану війни. | H11: 37367 | J11: 3066 | K11: 31437 | L11: 2559 | M11: 2406 | N11: 5028
A12: Загальна площа житлових будинків і нежитлових будівель на початок будівництва | B12: Миколаївська | C12: Житлові будинки | D12: Квадратний метр | E12: З 01.01.2024 року назви щодо типів будівель наведено відповідно до Національного класифікатора будівель і споруд (наказ Мінекономіки України від 16.05.2023 № 3573), до 01.01.2024 року - Номенклатури продукції будівництва (наказ Держстату України від 29.12.2017 № 356 (із змінами)). З 2025 року дані за показниками у розрізі типів місцевості (сільська, міська) та щодо загальної площі житлових будинків, прийнятих в експлуатацію, у розрахунку на 1 тис. осіб населення не формуються. З 2026 року за показниками змінено розріз за видами будівель. | F12: 1. Без урахування даних щодо житлових будинків та нежитлових будівель, показники за якими відсутні у Повідомленні про початок виконання будівельних робіт (Постанова КМУ від 13.04.2011 №466 (із змінами)); з 01.01.2024 року з урахуванням дач та садових будинків у житлових будинках. 2. Показники наведено наростаючим підсумком. | G12: Дані не оприлюднюються з метою виконання вимог Закону України "Про офіційну статистику" щодо забезпечення гарантій органів державної статистики щодо статистичної конфіденційності та/або відповідно до Закону України "Про захист інтересів суб’єктів подання звітності та інших документів у період дії воєнного стану або стану війни. | H12: 18335 | I12: 72296 | J12: 75530 | K12: 63512 | L12: 1666
A13: Загальна площа житлових будинків і нежитлових будівель на початок будівництва | B13: Львівська | C13: Житлові будинки | D13: Квадратний метр | E13: З 01.01.2024 року назви щодо типів будівель наведено відповідно до Національного класифікатора будівель і споруд (наказ Мінекономіки України від 16.05.2023 № 3573), до 01.01.2024 року - Номенклатури продукції будівництва (наказ Держстату України від 29.12.2017 № 356 (із змінами)). З 2025 року дані за показниками у розрізі типів місцевості (сільська, міська) та щодо загальної площі житлових будинків, прийнятих в експлуатацію, у розрахунку на 1 тис. осіб населення не формуються. З 2026 року за показниками змінено розріз за видами будівель. | F13: 1. Без урахування даних щодо житлових будинків та нежитлових будівель, показники за якими відсутні у Повідомленні про початок виконання будівельних робіт (Постанова КМУ від 13.04.2011 №466 (із змінами)); з 01.01.2024 року з урахуванням дач та садових будинків у житлових будинках. 2. Показники наведено наростаючим підсумком. | H13: 1223896 | I13: 1353221 | J13: 946056 | K13: 1108730 | L13: 1012973 | M13: 870373 | N13: 793210 | O13: 1165802
A14: Загальна площа житлових будинків і нежитлових будівель на початок будівництва | B14: Київська | C14: Житлові будинки | D14: Квадратний метр | E14: З 01.01.2024 року назви щодо типів будівель наведено відповідно до Національного класифікатора будівель і споруд (наказ Мінекономіки України від 16.05.2023 № 3573), до 01.01.2024 року - Номенклатури продукції будівництва (наказ Держстату України від 29.12.2017 № 356 (із змінами)). З 2025 року дані за показниками у розрізі типів місцевості (сільська, міська) та щодо загальної площі житлових будинків, прийнятих в експлуатацію, у розрахунку на 1 тис. осіб населення не формуються. З 2026 року за показниками змінено розріз за видами будівель. | F14: 1. Без урахування даних щодо житлових будинків та нежитлових будівель, показники за якими відсутні у Повідомленні про початок виконання будівельних робіт (Постанова КМУ від 13.04.2011 №466 (із змінами)); з 01.01.2024 року з урахуванням дач та садових будинків у житлових будинках. 2. Показники наведено наростаючим підсумком. | H14: 2558873 | I14: 1883804 | J14: 1820588 | K14: 2787073 | L14: 1867707 | M14: 616164 | N14: 636308 | O14: 1317062
A15: Загальна площа житлових будинків і нежитлових будівель на початок будівництва | B15: Полтавська | C15: Житлові будинки | D15: Квадратний метр | E15: З 01.01.2024 року назви щодо типів будівель наведено відповідно до Національного класифікатора будівель і споруд (наказ Мінекономіки України від 16.05.2023 № 3573), до 01.01.2024 року - Номенклатури продукції будівництва (наказ Держстату України від 29.12.2017 № 356 (із змінами)). З 2025 року дані за показниками у розрізі типів місцевості (сільська, міська) та щодо загальної площі житлових будинків, прийнятих в експлуатацію, у розрахунку на 1 тис. осіб населення не формуються. З 2026 року за показниками змінено розріз за видами будівель. | F15: 1. Без урахування даних щодо житлових будинків та нежитлових будівель, показники за якими відсутні у Повідомленні про початок виконання будівельних робіт (Постанова КМУ від 13.04.2011 №466 (із змінами)); з 01.01.2024 року з урахуванням дач та садових будинків у житлових будинках. 2. Показники наведено наростаючим підсумком. | G15: Відомості відсутні. | H15: 183598 | I15: 182425 | J15: 109422 | K15: 163482 | L15: 72556 | M15: 57036 | N15: 77694 | O15: 165898
A16: Загальна площа житлових будинків і нежитлових будівель на початок будівництва | B16: Рівненська | C16: Житлові будинки | D16: Квадратний метр | E16: З 01.01.2024 року назви щодо типів будівель наведено відповідно до Національного класифікатора будівель і споруд (наказ Мінекономіки України від 16.05.2023 № 3573), до 01.01.2024 року - Номенклатури продукції будівництва (наказ Держстату України від 29.12.2017 № 356 (із змінами)). З 2025 року дані за показниками у розрізі типів місцевості (сільська, міська) та щодо загальної площі житлових будинків, прийнятих в експлуатацію, у розрахунку на 1 тис. осіб населення не формуються. З 2026 року за показниками змінено розріз за видами будівель. | F16: 1. Без урахування даних щодо житлових будинків та нежитлових будівель, показники за якими відсутні у Повідомленні про початок виконання будівельних робіт (Постанова КМУ від 13.04.2011 №466 (із змінами)); з 01.01.2024 року з урахуванням дач та садових будинків у житлових будинках. 2. Показники наведено наростаючим підсумком. | H16: 108177 | I16: 81780 | J16: 164987 | K16: 171867 | L16: 194086 | M16: 62684 | N16: 97002 | O16: 173523
A17: Загальна площа житлових будинків і нежитлових будівель на початок будівництва | B17: Запорізька | C17: Житлові будинки | D17: Квадратний метр | E17: З 01.01.2024 року назви щодо типів будівель наведено відповідно до Національного класифікатора будівель і споруд (наказ Мінекономіки України від 16.05.2023 № 3573), до 01.01.2024 року - Номенклатури продукції будівництва (наказ Держстату України від 29.12.2017 № 356 (із змінами)). З 2025 року дані за показниками у розрізі типів місцевості (сільська, міська) та щодо загальної площі житлових будинків, прийнятих в експлуатацію, у розрахунку на 1 тис. осіб населення не формуються. З 2026 року за показниками змінено розріз за видами будівель. | F17: 1. Без урахування даних щодо житлових будинків та нежитлових будівель, показники за якими відсутні у Повідомленні про початок виконання будівельних робіт (Постанова КМУ від 13.04.2011 №466 (із змінами)); з 01.01.2024 року з урахуванням дач та садових будинків у житлових будинках. 2. Показники наведено наростаючим підсумком. | G17: Відомості відсутні. | H17: 92305 | I17: 27928 | J17: 41734 | K17: 192995 | L17: 68814
A18: Загальна площа житлових будинків і нежитлових будівель на початок будівництва | B18: Херсонська | C18: Житлові будинки | D18: Квадратний метр | E18: З 01.01.2024 року назви щодо типів будівель наведено відповідно до Національного класифікатора будівель і споруд (наказ Мінекономіки України від 16.05.2023 № 3573), до 01.01.2024 року - Номенклатури продукції будівництва (наказ Держстату України від 29.12.2017 № 356 (із змінами)). З 2025 року дані за показниками у розрізі типів місцевості (сільська, міська) та щодо загальної площі житлових будинків, прийнятих в експлуатацію, у розрахунку на 1 тис. осіб населення не формуються. З 2026 року за показниками змінено розріз за видами будівель. | F18: 1. Без урахування даних щодо житлових будинків та нежитлових будівель, показники за якими відсутні у Повідомленні про початок виконання будівельних робіт (Постанова КМУ від 13.04.2011 №466 (із змінами)); з 01.01.2024 року з урахуванням дач та садових будинків у житлових будинках. 2. Показники наведено наростаючим підсумком. | G18: Відомості відсутні. | H18: 31914 | I18: 62776 | J18: 57482 | K18: 70254 | L18: 10729 | O18: 22030
A19: Загальна площа житлових будинків і нежитлових будівель на початок будівництва | B19: Чернівецька | C19: Житлові будинки | D19: Квадратний метр | E19: З 01.01.2024 року назви щодо типів будівель наведено відповідно до Національного класифікатора будівель і споруд (наказ Мінекономіки України від 16.05.2023 № 3573), до 01.01.2024 року - Номенклатури продукції будівництва (наказ Держстату України від 29.12.2017 № 356 (із змінами)). З 2025 року дані за показниками у розрізі типів місцевості (сільська, міська) та щодо загальної площі житлових будинків, прийнятих в експлуатацію, у розрахунку на 1 тис. осіб населення не формуються. З 2026 року за показниками змінено розріз за видами будівель. | F19: 1. Без урахування даних щодо житлових будинків та нежитлових будівель, показники за якими відсутні у Повідомленні про початок виконання будівельних робіт (Постанова КМУ від 13.04.2011 №466 (із змінами)); з 01.01.2024 року з урахуванням дач та садових будинків у житлових будинках. 2. Показники наведено наростаючим підсумком. | H19: 113791 | I19: 219966 | J19: 131207 | K19: 251884 | L19: 60036 | M19: 225409 | N19: 84225 | O19: 145280
A20: Загальна площа житлових будинків і нежитлових будівель на початок будівництва | B20: Харківська | C20: Житлові будинки | D20: Квадратний метр | E20: З 01.01.2024 року назви щодо типів будівель наведено відповідно до Національного класифікатора будівель і споруд (наказ Мінекономіки України від 16.05.2023 № 3573), до 01.01.2024 року - Номенклатури продукції будівництва (наказ Держстату України від 29.12.2017 № 356 (із змінами)). З 2025 року дані за показниками у розрізі типів місцевості (сільська, міська) та щодо загальної площі житлових будинків, прийнятих в експлуатацію, у розрахунку на 1 тис. осіб населення не формуються. З 2026 року за показниками змінено розріз за видами будівель. | F20: 1. Без урахування даних щодо житлових будинків та нежитлових будівель, показники за якими відсутні у Повідомленні про початок виконання будівельних робіт (Постанова КМУ від 13.04.2011 №466 (із змінами)); з 01.01.2024 року з урахуванням дач та садових будинків у житлових будинках. 2. Показники наведено наростаючим підсумком. | G20: Дані не оприлюднюються з метою виконання вимог Закону України "Про офіційну статистику" щодо забезпечення гарантій органів державної статистики щодо статистичної конфіденційності та/або відповідно до Закону України "Про захист інтересів суб’єктів подання звітності та інших документів у період дії воєнного стану або стану війни. | H20: 617589 | I20: 627400 | J20: 181909 | K20: 702232 | L20: 214382 | M20: 131144
A21: Загальна площа житлових будинків і нежитлових будівель на початок будівництва | B21: Сумська | C21: Житлові будинки | D21: Квадратний метр | E21: З 01.01.2024 року назви щодо типів будівель наведено відповідно до Національного класифікатора будівель і споруд (наказ Мінекономіки України від 16.05.2023 № 3573), до 01.01.2024 року - Номенклатури продукції будівництва (наказ Держстату України від 29.12.2017 № 356 (із змінами)). З 2025 року дані за показниками у розрізі типів місцевості (сільська, міська) та щодо загальної площі житлових будинків, прийнятих в експлуатацію, у розрахунку на 1 тис. осіб населення не формуються. З 2026 року за показниками змінено розріз за видами будівель. | F21: 1. Без урахування даних щодо житлових будинків та нежитлових будівель, показники за якими відсутні у Повідомленні про початок виконання будівельних робіт (Постанова КМУ від 13.04.2011 №466 (із змінами)); з 01.01.2024 року з урахуванням дач та садових будинків у житлових будинках. 2. Показники наведено наростаючим підсумком. | G21: Відомості відсутні. | H21: 102030 | I21: 46352 | J21: 34185 | K21: 99821 | L21: 61798
A22: Загальна площа житлових будинків і нежитлових будівель на початок будівництва | B22: Київ | C22: Житлові будинки | D22: Квадратний метр | E22: З 01.01.2024 року назви щодо типів будівель наведено відповідно до Національного класифікатора будівель і споруд (наказ Мінекономіки України від 16.05.2023 № 3573), до 01.01.2024 року - Номенклатури продукції будівництва (наказ Держстату України від 29.12.2017 № 356 (із змінами)). З 2025 року дані за показниками у розрізі типів місцевості (сільська, міська) та щодо загальної площі житлових будинків, прийнятих в експлуатацію, у розрахунку на 1 тис. осіб населення не формуються. З 2026 року за показниками змінено розріз за видами будівель. | F22: 1. Без урахування даних щодо житлових будинків та нежитлових будівель, показники за якими відсутні у Повідомленні про початок виконання будівельних робіт (Постанова КМУ від 13.04.2011 №466 (із змінами)); з 01.01.2024 року з урахуванням дач та садових будинків у житлових будинках. 2. Показники наведено наростаючим підсумком. | H22: 3999872 | I22: 6407101 | J22: 1390040 | K22: 2979697 | L22: 878311 | M22: 299442 | N22: 335612 | O22: 709444
A23: Загальна площа житлових будинків і нежитлових будівель на початок будівництва | B23: Чернігівська | C23: Житлові будинки | D23: Квадратний метр | E23: З 01.01.2024 року назви щодо типів будівель наведено відповідно до Національного класифікатора будівель і споруд (наказ Мінекономіки України від 16.05.2023 № 3573), до 01.01.2024 року - Номенклатури продукції будівництва (наказ Держстату України від 29.12.2017 № 356 (із змінами)). З 2025 року дані за показниками у розрізі типів місцевості (сільська, міська) та щодо загальної площі житлових будинків, прийнятих в експлуатацію, у розрахунку на 1 тис. осіб населення не формуються. З 2026 року за показниками змінено розріз за видами будівель. | F23: 1. Без урахування даних щодо житлових будинків та нежитлових будівель, показники за якими відсутні у Повідомленні про початок виконання будівельних робіт (Постанова КМУ від 13.04.2011 №466 (із змінами)); з 01.01.2024 року з урахуванням дач та садових будинків у житлових будинках. 2. Показники наведено наростаючим підсумком. | G23: Відомості відсутні. | H23: 105718 | I23: 201888 | J23: 170290 | K23: 158156 | L23: 101515 | O23: 6556
A24: Загальна площа житлових будинків і нежитлових будівель на початок будівництва | B24: Тернопільська | C24: Житлові будинки | D24: Квадратний метр | E24: З 01.01.2024 року назви щодо типів будівель наведено відповідно до Національного класифікатора будівель і споруд (наказ Мінекономіки України від 16.05.2023 № 3573), до 01.01.2024 року - Номенклатури продукції будівництва (наказ Держстату України від 29.12.2017 № 356 (із змінами)). З 2025 року дані за показниками у розрізі типів місцевості (сільська, міська) та щодо загальної площі житлових будинків, прийнятих в експлуатацію, у розрахунку на 1 тис. осіб населення не формуються. З 2026 року за показниками змінено розріз за видами будівель. | F24: 1. Без урахування даних щодо житлових будинків та нежитлових будівель, показники за якими відсутні у Повідомленні про початок виконання будівельних робіт (Постанова КМУ від 13.04.2011 №466 (із змінами)); з 01.01.2024 року з урахуванням дач та садових будинків у житлових будинках. 2. Показники наведено наростаючим підсумком. | H24: 383768 | I24: 214049 | J24: 152273 | K24: 323261 | L24: 258797 | M24: 109995 | N24: 63555 | O24: 232956
A25: Загальна площа житлових будинків і нежитлових будівель на початок будівництва | B25: Черкаська | C25: Житлові будинки | D25: Квадратний метр | E25: З 01.01.2024 року назви щодо типів будівель наведено відповідно до Національного класифікатора будівель і споруд (наказ Мінекономіки України від 16.05.2023 № 3573), до 01.01.2024 року - Номенклатури продукції будівництва (наказ Держстату України від 29.12.2017 № 356 (із змінами)). З 2025 року дані за показниками у розрізі типів місцевості (сільська, міська) та щодо загальної площі житлових будинків, прийнятих в експлуатацію, у розрахунку на 1 тис. осіб населення не формуються. З 2026 року за показниками змінено розріз за видами будівель. | F25: 1. Без урахування даних щодо житлових будинків та нежитлових будівель, показники за якими відсутні у Повідомленні про початок виконання будівельних робіт (Постанова КМУ від 13.04.2011 №466 (із змінами)); з 01.01.2024 року з урахуванням дач та садових будинків у житлових будинках. 2. Показники наведено наростаючим підсумком. | H25: 131213 | I25: 97848 | J25: 70632 | K25: 200874 | L25: 138791 | M25: 110934 | N25: 125567 | O25: 96896
A26: Загальна площа житлових будинків і нежитлових будівель на початок будівництва | B26: Хмельницька | C26: Житлові будинки | D26: Квадратний метр | E26: З 01.01.2024 року назви щодо типів будівель наведено відповідно до Національного класифікатора будівель і споруд (наказ Мінекономіки України від 16.05.2023 № 3573), до 01.01.2024 року - Номенклатури продукції будівництва (наказ Держстату України від 29.12.2017 № 356 (із змінами)). З 2025 року дані за показниками у розрізі типів місцевості (сільська, міська) та щодо загальної площі житлових будинків, прийнятих в експлуатацію, у розрахунку на 1 тис. осіб населення не формуються. З 2026 року за показниками змінено розріз за видами будівель. | F26: 1. Без урахування даних щодо житлових будинків та нежитлових будівель, показники за якими відсутні у Повідомленні про початок виконання будівельних робіт (Постанова КМУ від 13.04.2011 №466 (із змінами)); з 01.01.2024 року з урахуванням дач та садових будинків у житлових будинках. 2. Показники наведено наростаючим підсумком. | H26: 220923 | I26: 257659 | J26: 323213 | K26: 553797 | L26: 330875 | M26: 313144 | N26: 184756 | O26: 210828

Sheet Raw data _m2region expl
A1: Показник | B1: Територіальний розріз | C1: Тип будівлі | D1: Тип місцевості | E1: Періодичність | F1: Одиниця виміру | G1: Масштабування | H1: 2018 | I1: 2019 | J1: 2020 | K1: 2021 | L1: 2022 | M1: 2023 | N1: 2024 | O1: 2025
A2: Загальна площа житлових будинків, прийнятих в експлуатацію | B2: Дніпропетровська | C2: Житлові будинки | D2: Загалом | E2: Квартальна | F2: Квадратний метр | G2: Одиниці | H2: 283525 | I2: 414258 | J2: 258993 | K2: 374115 | L2: 181978 | M2: 235123 | N2: 304272 | O2: 286515
A3: Загальна площа житлових будинків, прийнятих в експлуатацію | B3: Україна | C3: Житлові будинки | D3: Загалом | E3: Квартальна | F3: Квадратний метр | G3: Одиниці | H3: 8689356 | I3: 11029327 | J3: 8451221 | K3: 11433790 | L3: 7110224 | M3: 7380752 | N3: 9758881 | O3: 9552933
A4: Загальна площа житлових будинків, прийнятих в експлуатацію | B4: Вінницька | C4: Житлові будинки | D4: Загалом | E4: Квартальна | F4: Квадратний метр | G4: Одиниці | H4: 223899 | I4: 287392 | J4: 321537 | K4: 365873 | L4: 404515 | M4: 658558 | N4: 546708 | O4: 520927
A5: Загальна площа житлових будинків, прийнятих в експлуатацію | B5: Волинська | C5: Житлові будинки | D5: Загалом | E5: Квартальна | F5: Квадратний метр | G5: Одиниці | H5: 371290 | I5: 437309 | J5: 355583 | K5: 341228 | L5: 274584 | M5: 316277 | N5: 443550 | O5: 429379
A6: Загальна площа житлових будинків, прийнятих в експлуатацію | B6: Донецька | C6: Житлові будинки | D6: Загалом | E6: Квартальна | F6: Квадратний метр | G6: Одиниці | H6: 40584 | I6: 63125 | J6: 47312 | K6: 47969 | L6: 3683 | M6: 5597 | N6: 26961 | O6: 31916
A7: Загальна площа житлових будинків, прийнятих в експлуатацію | B7: Закарпатська | C7: Житлові будинки | D7: Загалом | E7: Квартальна | F7: Квадратний метр | G7: Одиниці | H7: 428736 | I7: 506918 | J7: 390975 | K7: 416083 | L7: 309252 | M7: 364224 | N7: 483979 | O7: 496829
A8: Загальна площа житлових будинків, прийнятих в експлуатацію | B8: Житомирська | C8: Житлові будинки | D8: Загалом | E8: Квартальна | F8: Квадратний метр | G8: Одиниці | H8: 146281 | I8: 195730 | J8: 154201 | K8: 195896 | L8: 117651 | M8: 111886 | N8: 179370 | O8: 136802
A9: Загальна площа житлових будинків, прийнятих в експлуатацію | B9: Запорізька | C9: Житлові будинки | D9: Загалом | E9: Квартальна | F9: Квадратний метр | G9: Одиниці | H9: 68246 | I9: 90296 | J9: 52636 | K9: 61498 | L9: 19155 | M9: 21528 | N9: 42003 | O9: 36691
A10: Загальна площа житлових будинків, прийнятих в експлуатацію | B10: Київ | C10: Житлові будинки | D10: Загалом | E10: Квартальна | F10: Квадратний метр | G10: Одиниці | H10: 1255854 | I10: 1113986 | J10: 864874 | K10: 1961648 | L10: 908081 | M10: 1013832 | N10: 1412122 | O10: 1190992
A11: Загальна площа житлових будинків, прийнятих в експлуатацію | B11: Рівненська | C11: Житлові будинки | D11: Загалом | E11: Квартальна | F11: Квадратний метр | G11: Одиниці | H11: 319285 | I11: 351811 | J11: 293057 | K11: 270753 | L11: 244185 | M11: 231914 | N11: 391424 | O11: 322454
A12: Загальна площа житлових будинків, прийнятих в експлуатацію | B12: Чернігівська | C12: Житлові будинки | D12: Загалом | E12: Квартальна | F12: Квадратний метр | G12: Одиниці | H12: 97853 | I12: 142890 | J12: 95625 | K12: 96260 | L12: 102999 | M12: 71346 | N12: 109747 | O12: 97093
A13: Загальна площа житлових будинків, прийнятих в експлуатацію | B13: Одеська | C13: Житлові будинки | D13: Загалом | E13: Квартальна | F13: Квадратний метр | G13: Одиниці | H13: 567842 | I13: 1087227 | J13: 525092 | K13: 1038857 | L13: 694306 | M13: 294506 | N13: 581221 | O13: 799656
... A26: Загальна площа житлових будинків, прийнятих в експлуатацію | B26: Миколаївська | C26: Житлові будинки | D26: Загалом | E26: Квартальна | F26: Квадратний метр | G26: Одиниці | H26: 51302 | I26: 112013 | J26: 61897 | K26: 59586 | L26: 35484 | M26: 33478 | N26: 33667 | O26: 51028

Sheet Rawdata _flat expl
A1: Показник | B1: Територіальний розріз | C1: Тип будівлі | D1: Тип місцевості | E1: Періодичність | F1: Одиниця виміру | G1: Масштабування | H1: Кількість десяткових знаків | I1: Спеціальне значення даних | J1: Примітки набору даних | K1: Примітки часового ряду | L1: Примітки спостереження | M1: 2018 | N1: 2019 | O1: 2020 | P1: 2021 | Q1: 2022 | R1: 2023 | S1: 2024 | T1: 2025
A2: Кількість квартир у житлових будинках, прийнятих в експлуатацію | B2: Україна | C2: Житлові будинки без житлових будинків для колективного проживання | D2: Загалом | E2: Квартальна | F2: Одиниця | G2: Одиниці | H2: Нуль | J2: З 01.01.2024 року назви щодо типів будівель наведено відповідно до Національного класифікатора будівель і споруд (наказ Мінекономіки України від 16.05.2023 № 3573), до 01.01.2024 року - Номенклатури продукції будівництва (наказ Держстату України від 29.12.2017 № 356 (із змінами)). З 2025 року дані за показниками у розрізі типів місцевості (сільська, міська) та щодо загальної площі житлових будинків, прийнятих в експлуатацію, у розрахунку на 1 тис. осіб населення не формуються. З 2026 року за показниками змінено розріз за видами будівель. | K2: 1. Дані наведено без урахування тимчасово окупованих російською федерацією територій та частини територій, на яких ведуться (велися) бойові дії. 2. З урахуванням прийнятих в експлуатацію житлових будинків відповідно до встановленого Порядку (наказ Мінрегіону від 03.07.2018 № 158 (зі змінами)); з 01.01.2024 з урахуванням дач та садових будинків. 3. Показники наведено наростаючим підсумком. | M2: 103141 | N2: 125986 | O2: 96504 | P2: 151720 | Q2: 92593 | R2: 89255 | S2: 118452 | T2: 117578
A3: Кількість квартир у житлових будинках, прийнятих в експлуатацію | B3: Волинська | C3: Житлові будинки без житлових будинків для колективного проживання | D3: Загалом | E3: Квартальна | F3: Одиниця | G3: Одиниці | H3: Нуль | I3: Конфіденційна статистична інформація | J3: З 01.01.2024 року назви щодо типів будівель наведено відповідно до Національного класифікатора будівель і споруд (наказ Мінекономіки України від 16.05.2023 № 3573), до 01.01.2024 року - Номенклатури продукції будівництва (наказ Держстату України від 29.12.2017 № 356 (із змінами)). З 2025 року дані за показниками у розрізі типів місцевості (сільська, міська) та щодо загальної площі житлових будинків, прийнятих в експлуатацію, у розрахунку на 1 тис. осіб населення не формуються. З 2026 року за показниками змінено розріз за видами будівель. | K3: 1. З урахуванням прийнятих в експлуатацію житлових будинків відповідно до встановленого Порядку (наказ Мінрегіону від 03.07.2018 № 158 (зі змінами)); з 01.01.2024 з урахуванням дач та садових будинків. 2. Показники наведено наростаючим підсумком. | M3: 3811 | N3: 4106 | O3: 3532 | P3: 3473 | Q3: 3188 | R3: 3496 | S3: 5061 | T3: 4588
A4: Кількість квартир у житлових будинках, прийнятих в експлуатацію | B4: Миколаївська | C4: Житлові будинки без житлових будинків для колективного проживання | D4: Загалом | E4: Квартальна | F4: Одиниця | G4: Одиниці | H4: Нуль | J4: З 01.01.2024 року назви щодо типів будівель наведено відповідно до Національного класифікатора будівель і споруд (наказ Мінекономіки України від 16.05.2023 № 3573), до 01.01.2024 року - Номенклатури продукції будівництва (наказ Держстату України від 29.12.2017 № 356 (із змінами)). З 2025 року дані за показниками у розрізі типів місцевості (сільська, міська) та щодо загальної площі житлових будинків, прийнятих в експлуатацію, у розрахунку на 1 тис. осіб населення не формуються. З 2026 року за показниками змінено розріз за видами будівель. | K4: 1. З урахуванням прийнятих в експлуатацію житлових будинків відповідно до встановленого Порядку (наказ Мінрегіону від 03.07.2018 № 158 (зі змінами)); з 01.01.2024 з урахуванням дач та садових будинків. 2. Показники наведено наростаючим підсумком. | M4: 431 | N4: 1127 | O4: 594 | P4: 629 | Q4: 379 | R4: 271 | S4: 264 | T4: 556
A5: Кількість квартир у житлових будинках, прийнятих в експлуатацію | B5: Вінницька | C5: Житлові будинки без житлових будинків для колективного проживання | D5: Загалом | E5: Квартальна | F5: Одиниця | G5: Одиниці | H5: Нуль | J5: З 01.01.2024 року назви щодо типів будівель наведено відповідно до Національного класифікатора будівель і споруд (наказ Мінекономіки України від 16.05.2023 № 3573), до 01.01.2024 року - Номенклатури продукції будівництва (наказ Держстату України від 29.12.2017 № 356 (із змінами)). З 2025 року дані за показниками у розрізі типів місцевості (сільська, міська) та щодо загальної площі житлових будинків, прийнятих в експлуатацію, у розрахунку на 1 тис. осіб населення не формуються. З 2026 року за показниками змінено розріз за видами будівель. | K5: 1. З урахуванням прийнятих в експлуатацію житлових будинків відповідно до встановленого Порядку (наказ Мінрегіону від 03.07.2018 № 158 (зі змінами)); з 01.01.2024 з урахуванням дач та садових будинків. 2. Показники наведено наростаючим підсумком. | M5: 2475 | N5: 3165 | O5: 3868 | P5: 4622 | Q5: 5710 | R5: 10313 | S5: 8001 | T5: 7142
A6: Кількість квартир у житлових будинках, прийнятих в експлуатацію | B6: Львівська | C6: Житлові будинки без житлових будинків для колективного проживання | D6: Загалом | E6: Квартальна | F6: Одиниця | G6: Одиниці | H6: Нуль | I6: Конфіденційна статистична інформація | J6: З 01.01.2024 року назви щодо типів будівель наведено відповідно до Національного класифікатора будівель і споруд (наказ Мінекономіки України від 16.05.2023 № 3573), до 01.01.2024 року - Номенклатури продукції будівництва (наказ Держстату України від 29.12.2017 № 356 (із змінами)). З 2025 року дані за показниками у розрізі типів місцевості (сільська, міська) та щодо загальної площі житлових будинків, прийнятих в експлуатацію, у розрахунку на 1 тис. осіб населення не формуються. З 2026 року за показниками змінено розріз за видами будівель. | K6: 1. З урахуванням прийнятих в експлуатацію житлових будинків відповідно до встановленого Порядку (наказ Мінрегіону від 03.07.2018 № 158 (зі змінами)); з 01.01.2024 з урахуванням дач та садових будинків. 2. Показники наведено наростаючим підсумком. | M6: 9637 | N6: 14110 | O6: 10873 | P6: 14689 | Q6: 8689 | R6: 8635 | S6: 12627 | T6: 12594
A7: Кількість квартир у житлових будинках, прийнятих в експлуатацію | B7: Кіровоградська | C7: Житлові будинки без житлових будинків для колективного проживання | D7: Загалом | E7: Квартальна | F7: Одиниця | G7: Одиниці | H7: Нуль | J7: З 01.01.2024 року назви щодо типів будівель наведено відповідно до Національного класифікатора будівель і споруд (наказ Мінекономіки України від 16.05.2023 № 3573), до 01.01.2024 року - Номенклатури продукції будівництва (наказ Держстату України від 29.12.2017 № 356 (із змінами)). З 2025 року дані за показниками у розрізі типів місцевості (сільська, міська) та щодо загальної площі житлових будинків, прийнятих в експлуатацію, у розрахунку на 1 тис. осіб населення не формуються. З 2026 року за показниками змінено розріз за видами будівель. | K7: 1. З урахуванням прийнятих в експлуатацію житлових будинків відповідно до встановленого Порядку (наказ Мінрегіону від 03.07.2018 № 158 (зі змінами)); з 01.01.2024 з урахуванням дач та садових будинків. 2. Показники наведено наростаючим підсумком. | M7: 398 | N7: 608 | O7: 617 | P7: 521 | Q7: 287 | R7: 237 | S7: 938 | T7: 335
A8: Кількість квартир у житлових будинках, прийнятих в експлуатацію | B8: Київська | C8: Житлові будинки без житлових будинків для колективного проживання | D8: Загалом | E8: Квартальна | F8: Одиниця | G8: Одиниці | H8: Нуль | J8: З 01.01.2024 року назви щодо типів будівель наведено відповідно до Національного класифікатора будівель і споруд (наказ Мінекономіки України від 16.05.2023 № 3573), до 01.01.2024 року - Номенклатури продукції будівництва (наказ Держстату України від 29.12.2017 № 356 (із змінами)). З 2025 року дані за показниками у розрізі типів місцевості (сільська, міська) та щодо загальної площі житлових будинків, прийнятих в експлуатацію, у розрахунку на 1 тис. осіб населення не формуються. З 2026 року за показниками змінено розріз за видами будівель. | K8: 1. З урахуванням прийнятих в експлуатацію житлових будинків відповідно до встановленого Порядку (наказ Мінрегіону від 03.07.2018 № 158 (зі змінами)); з 01.01.2024 з урахуванням дач та садових будинків. 2. Показники наведено наростаючим підсумком. | M8: 19108 | N8: 22639 | O8: 22032 | P8: 26284 | Q8: 19686 | R8: 15903 | S8: 21108 | T8: 22593
A9: Кількість квартир у житлових будинках, прийнятих в експлуатацію | B9: Житомирська | C9: Житлові будинки без житлових будинків для колективного проживання | D9: Загалом | E9: Квартальна | F9: Одиниця | G9: Одиниці | H9: Нуль | I9: Конфіденційна статистична інформація | J9: З 01.01.2024 року назви щодо типів будівель наведено відповідно до Національного класифікатора будівель і споруд (наказ Мінекономіки України від 16.05.2023 № 3573), до 01.01.2024 року - Номенклатури продукції будівництва (наказ Держстату України від 29.12.2017 № 356 (із змінами)). З 2025 року дані за показниками у розрізі типів місцевості (сільська, міська) та щодо загальної площі житлових будинків, прийнятих в експлуатацію, у розрахунку на 1 тис. осіб населення не формуються. З 2026 року за показниками змінено розріз за видами будівель. | K9: 1. З урахуванням прийнятих в експлуатацію житлових будинків відповідно до встановленого Порядку (наказ Мінрегіону від 03.07.2018 № 158 (зі змінами)); з 01.01.2024 з урахуванням дач та садових будинків. 2. Показники наведено наростаючим підсумком. | M9: 1332 | N9: 1817 | O9: 1523 | P9: 2367 | Q9: 1416 | R9: 1129 | S9: 2073 | T9: 1220
A10: Кількість квартир у житлових будинках, прийнятих в експлуатацію | B10: Одеська | C10: Житлові будинки без житлових будинків для колективного проживання | D10: Загалом | E10: Квартальна | F10: Одиниця | G10: Одиниці | H10: Нуль | J10: З 01.01.2024 року назви щодо типів будівель наведено відповідно до Національного класифікатора будівель і споруд (наказ Мінекономіки України від 16.05.2023 № 3573), до 01.01.2024 року - Номенклатури продукції будівництва (наказ Держстату України від 29.12.2017 № 356 (із змінами)). З 2025 року дані за показниками у розрізі типів місцевості (сільська, міська) та щодо загальної площі житлових будинків, прийнятих в експлуатацію, у розрахунку на 1 тис. осіб населення не формуються. З 2026 року за показниками змінено розріз за видами будівель. | K10: 1. З урахуванням прийнятих в експлуатацію житлових будинків відповідно до встановленого Порядку (наказ Мінрегіону від 03.07.2018 № 158 (зі змінами)); з 01.01.2024 з урахуванням дач та садових будинків. 2. Показники наведено наростаючим підсумком. | M10: 8569 | N10: 16819 | O10: 7251 | P10: 17350 | Q10: 11289 | R10: 3608 | S10: 7950 | T10: 12993
A11: Кількість квартир у житлових будинках, прийнятих в експлуатацію | B11: Донецька | C11: Житлові будинки без житлових будинків для колективного проживання | D11: Загалом | E11: Квартальна | F11: Одиниця | G11: Одиниці | H11: Нуль | I11: Конфіденційна статистична інформація | J11: З 01.01.2024 року назви щодо типів будівель наведено відповідно до Національного класифікатора будівель і споруд (наказ Мінекономіки України від 16.05.2023 № 3573), до 01.01.2024 року - Номенклатури продукції будівництва (наказ Держстату України від 29.12.2017 № 356 (із змінами)). З 2025 року дані за показниками у розрізі типів місцевості (сільська, міська) та щодо загальної площі житлових будинків, прийнятих в експлуатацію, у розрахунку на 1 тис. осіб населення не формуються. З 2026 року за показниками змінено розріз за видами будівель. | K11: 1. Дані наведено без урахування тимчасово окупованих російською федерацією територій та частини територій, на яких ведуться (велися) бойові дії. 2. З урахуванням прийнятих в експлуатацію житлових будинків відповідно до встановленого Порядку (наказ Мінрегіону від 03.07.2018 № 158 (зі змінами)); з 01.01.2024 з урахуванням дач та садових будинків. 3. Показники наведено наростаючим підсумком. | M11: 328 | N11: 485 | O11: 360 | P11: 447 | Q11: 41 | R11: 43 | S11: 178 | T11: 211
